Workbook

Sheet Legend
A1: AI use case library and client audit
A2: Use Case Master: one row per use case. Read each row left to right: what it is, how to recognize it in an interview, data needed, technology, what to prescribe (Form), tools, what to measure first, risks, and when NOT to prescribe it.
A3: Filter any column with the header arrows (by industry, department, business type, technology or form).
A4: Forms (what to prescribe): the 11 concrete forms a recommendation can take. Forms 1-7 are LLM-related; 8-11 are other approaches.
A5: When AI is not needed: situations where the honest answer is no, and what to suggest instead.
A6: Client audit (columns P-U): fill in per client: existing tool, whether it has an AI feature, enabled, used, % of the need it already covers. Gap and next step calculate automatically (threshold in Lookups!B26).
A7: Blue text = cells you type in. Yellow-shaded cells in row 2 are EXAMPLE audit values; overwrite them. 40 empty rows at the bottom are ready for client-specific use cases.
A9: Important: ratings, tool names and risk notes are general starting points from my general knowledge, not facts about a specific company. Vendor products and features change quickly: verify tools and licensing before recommending. No savings figures are included on purpose; set them from each client's baseline and test in a pilot.

Sheet Use Case Master
A1: ID | B1: Business type | C1: Industry | D1: Department | E1: Specific use case | F1: How to recognize it (signals in the interview) | G1: Data needed | H1: Technology | I1: Form to prescribe | J1: Example tools (check current) | K1: Metric to baseline first | L1: Main risk and mitigation | M1: When NOT to prescribe | N1: Need level | O1: Cost range | P1: Client's existing tool | Q1: Has AI feature? | R1: Enabled? | S1: Used? | T1: Covers the need (%) | U1: Gap (%) | V1: Suggested next step | W1: Notes
A2: U01 | B2: Conversation-heavy | C2: Cross-industry | D2: Customer service | E2: Answer first-line questions from the help center | F2: Same questions keep coming; agents search old tickets; first response is slow; a help center exists | G2: Help articles, FAQs, past tickets (cleaned) | H2: RAG + LLM | I2: 2 Feature in existing tool | J2: Zendesk AI, Intercom Fin, Freshdesk Freddy; custom RAG if none | K2: First response time, tickets per agent, share resolved without human | L2: Wrong answers: show sources, escalate when unsure, agents review at first | M2: Very few tickets per month, or the help center is outdated or empty (fix content first) | N2: Very high | O2: Low | P2: Zendesk (Advanced AI add-on) | Q2: Yes | R2: No | S2: No | T2: 0.75 | U2: =IF(T2="","",1-T2) -> 0.25 | V2: =IF(P2="","",IF(Q2="No","No AI in current tool: consider add-on or API-based option",IF(T2="","Estimate how much the tool covers",IF(T2>=Lookups!$B$26,IF(AND(R2="Yes",S2="Yes"),"Covered: keep and monitor","Switch on and train people on the existing feature"),"Partial: configure the tool, then fill the gap")))) -> Switch on and train people on the existing feature | W2: EXAMPLE audit values - overwrite with real client data
A3: U02 | B3: Conversation-heavy | C3: Cross-industry | D3: Customer service | E3: Ticket triage, tagging, routing and summaries | F3: Tickets are misrouted or tagged by hand; agents reread long threads | G3: Ticket text and existing categories | H3: LLM | I3: 2 Feature in existing tool | J3: Helpdesk built-ins; LLM API for custom rules | K3: Misrouting rate, time to first assignment, handling time | L3: Low: human can fix tags; avoid auto-closing tickets | M3: Tiny team where one person sees every ticket anyway | N3: High | O3: Low | U3: =IF(T3="","",1-T3) | V3: =IF(P3="","",IF(Q3="No","No AI in current tool: consider add-on or API-based option",IF(T3="","Estimate how much the tool covers",IF(T3>=Lookups!$B$26,IF(AND(R3="Yes",S3="Yes"),"Covered: keep and monitor","Switch on and train people on the existing feature"),"Partial: configure the tool, then fill the gap"))))
A4: U03 | B4: Conversation-heavy | C4: Cross-industry | D4: Sales & marketing | E4: Lead scoring | F4: Sales chases leads without priority; CRM holds a long history of won and lost deals | G4: CRM history: lead source, activity, outcome | H4: Classical ML | I4: 2 Feature in existing tool | J4: HubSpot, Salesforce built-in scoring; custom model if data is rich | K4: Conversion rate by lead tier, time per won deal | L4: Biased or stale scoring: retrain, compare with a simple rules baseline | M4: Few deals in history or inconsistent CRM entries; a rules-based score is enough | N4: High | O4: Medium | U4: =IF(T4="","",1-T4) | V4: =IF(P4="","",IF(Q4="No","No AI in current tool: consider add-on or API-based option",IF(T4="","Estimate how much the tool covers",IF(T4>=Lookups!$B$26,IF(AND(R4="Yes",S4="Yes"),"Covered: keep and monitor","Switch on and train people on the existing feature"),"Partial: configure the tool, then fill the gap"))))
A5: U04 | B5: Document-heavy | C5: Cross-industry | D5: Sales & marketing | E5: Proposal and RFP drafting from past answers | F5: Sales engineers rewrite similar answers; each RFP takes days; an answer library already exists | G5: Past proposals, product documentation | H5: RAG + LLM | I5: 4 RAG on documents | J5: Loopio, Responsive; Microsoft Copilot; custom RAG | K5: Hours per proposal, win rate, review corrections | L5: Wrong commitments: mandatory expert review, source citation | M5: Few proposals per year; every proposal is unique | N5: High | O5: Medium | U5: =IF(T5="","",1-T5) | V5: =IF(P5="","",IF(Q5="No","No AI in current tool: consider add-on or API-based option",IF(T5="","Estimate how much the tool covers",IF(T5>=Lookups!$B$26,IF(AND(R5="Yes",S5="Yes"),"Covered: keep and monitor","Switch on and train people on the existing feature"),"Partial: configure the tool, then fill the gap"))))
A6: U05 | B6: Conversation-heavy | C6: Cross-industry | D6: Sales & marketing | E6: Content drafting and localization | F6: Small marketing team, high demand for texts in several languages | G6: Brand guidelines, past content | H6: LLM | I6: 1 Ready assistant | J6: ChatGPT, Claude, Copilot, Gemini | K6: Drafts per week, editing time, cost per translated page | L6: Brand tone, factual errors, confidential data in prompts: usage policy | M6: Strict regulated claims (pharma, finance) without review process | N6: Medium | O6: Low | U6: =IF(T6="","",1-T6) | V6: =IF(P6="","",IF(Q6="No","No AI in current tool: consider add-on or API-based option",IF(T6="","Estimate how much the tool covers",IF(T6>=Lookups!$B$26,IF(AND(R6="Yes",S6="Yes"),"Covered: keep and monitor","Switch on and train people on the existing feature"),"Partial: configure the tool, then fill the gap"))))
A7: U06 | B7: Document-heavy | C7: Cross-industry | D7: Finance & accounting | E7: Invoice and receipt data extraction | F7: Staff retype invoices into the ERP; many suppliers with different formats | G7: Invoices (PDF, scans), ERP supplier and PO data | H7: Document AI + LLM | I7: 2 Feature in existing tool | J7: ERP/accounting built-ins, Azure Document Intelligence, ABBYY, Rossum | K7: Cost per invoice, processing time, error rate, share needing manual fix | L7: Misread amounts: validation against PO, human check on low confidence | M7: Low volume, or suppliers already send structured e-invoices (integrate instead) | N7: High | O7: Medium | U7: =IF(T7="","",1-T7) | V7: =IF(P7="","",IF(Q7="No","No AI in current tool: consider add-on or API-based option",IF(T7="","Estimate how much the tool covers",IF(T7>=Lookups!$B$26,IF(AND(R7="Yes",S7="Yes"),"Covered: keep and monitor","Switch on and train people on the existing feature"),"Partial: configure the tool, then fill the gap"))))
A8: U07 | B8: Transaction-heavy | C8: Cross-industry | D8: Finance & accounting | E8: Anomaly detection in payments and expenses | F8: Audits find errors late; duplicate or odd payments appear; lots of transactions | G8: Transaction history, vendor master data | H8: Anomaly detection | I8: 8 Classical ML project | J8: ERP/spend tools with built-in flags; custom isolation-forest style models | K8: Amount recovered, false-alert rate, detection delay | L8: Alert flood: tune thresholds, review queue | M8: Small transaction volume; simple rules (duplicates, limits) catch most issues | N8: Medium | O8: Medium | U8: =IF(T8="","",1-T8) | V8: =IF(P8="","",IF(Q8="No","No AI in current tool: consider add-on or API-based option",IF(T8="","Estimate how much the tool covers",IF(T8>=Lookups!$B$26,IF(AND(R8="Yes",S8="Yes"),"Covered: keep and monitor","Switch on and train people on the existing feature"),"Partial: configure the tool, then fill the gap"))))
A9: U08 | B9: Transaction-heavy | C9: Cross-industry | D9: Operations | E9: Demand forecasting by product or location | F9: Stockouts and overstock at once; forecasts made in Excel by gut; years of sales history by SKU | G9: Sales history by SKU, prices, promotions, calendar | H9: Classical ML | I9: 8 Classical ML project | J9: Forecasting modules in ERP/planning tools; Python (gradient boosting) | K9: Forecast error (MAPE), stockout rate, inventory days | L9: Overtrusting forecasts: always compare with a simple baseline first | M9: Mostly new products with no history, or few SKUs where simple averages work | N9: High | O9: Medium | U9: =IF(T9="","",1-T9) | V9: =IF(P9="","",IF(Q9="No","No AI in current tool: consider add-on or API-based option",IF(T9="","Estimate how much the tool covers",IF(T9>=Lookups!$B$26,IF(AND(R9="Yes",S9="Yes"),"Covered: keep and monitor","Switch on and train people on the existing feature"),"Partial: configure the tool, then fill the gap"))))
A10: U09 | B10: Document-heavy | C10: Cross-industry | D10: HR | E10: Internal policy and benefits Q&A | F10: HR answers the same questions all day; policies are written and up to date | G10: HR policies, handbooks | H10: RAG + LLM | I10: 4 RAG on documents | J10: Microsoft Copilot, HR suite assistants, custom RAG | K10: HR tickets per month, answer time | L10: Wrong or confidential answers: access control, link to policy source | M10: Policies are outdated or contradictory; fix them first | N10: Medium | O10: Low | U10: =IF(T10="","",1-T10) | V10: =IF(P10="","",IF(Q10="No","No AI in current tool: consider add-on or API-based option",IF(T10="","Estimate how much the tool covers",IF(T10>=Lookups!$B$26,IF(AND(R10="Yes",S10="Yes"),"Covered: keep and monitor","Switch on and train people on the existing feature"),"Partial: configure the tool, then fill the gap"))))
A11: U10 | B11: Expert judgment | C11: Cross-industry | D11: HR | E11: CV screening support | F11: Hundreds of applications per role; recruiters overloaded | G11: CVs, job descriptions, past hiring outcomes | H11: LLM | I11: 3 LLM via API | J11: ATS built-in features | K11: Time to shortlist, quality of hire | L11: High-risk: bias and legal exposure (employment AI is high-risk under the EU AI Act); human decides, document criteria | M11: Never as auto-reject; avoid if no bias testing is possible | N11: Medium | O11: High | U11: =IF(T11="","",1-T11) | V11: =IF(P11="","",IF(Q11="No","No AI in current tool: consider add-on or API-based option",IF(T11="","Estimate how much the tool covers",IF(T11>=Lookups!$B$26,IF(AND(R11="Yes",S11="Yes"),"Covered: keep and monitor","Switch on and train people on the existing feature"),"Partial: configure the tool, then fill the gap"))))
A12: U11 | B12: Document-heavy | C12: Cross-industry | D12: Legal & compliance | E12: Contract clause extraction and review support | F12: Lawyers read similar contracts line by line; playbook of preferred clauses exists | G12: Contracts, clause playbook | H12: RAG + LLM | I12: 3 LLM via API | J12: Harvey, Luminance, Microsoft Copilot, custom API workflow | K12: Review time per contract, missed-clause rate | L12: Missed or invented clauses: lawyer signs off every output; confidentiality terms with vendor | M12: Rare, bespoke contracts with little repetition | N12: High | O12: Medium | U12: =IF(T12="","",1-T12) | V12: =IF(P12="","",IF(Q12="No","No AI in current tool: consider add-on or API-based option",IF(T12="","Estimate how much the tool covers",IF(T12>=Lookups!$B$26,IF(AND(R12="Yes",S12="Yes"),"Covered: keep and monitor","Switch on and train people on the existing feature"),"Partial: configure the tool, then fill the gap"))))
A13: U12 | B13: Expert judgment | C13: Cross-industry | D13: IT | E13: Code assistant for developers | F13: In-house developers; routine coding, tests and documentation take time | G13: Codebase (stays under company control) | H13: LLM | I13: 1 Ready assistant | J13: GitHub Copilot, Claude Code, Cursor | K13: Cycle time, pull request throughput, defect rate | L13: Insecure code, leaked source: code review, license and data settings | M13: No developers | N13: High | O13: Low | U13: =IF(T13="","",1-T13) | V13: =IF(P13="","",IF(Q13="No","No AI in current tool: consider add-on or API-based option",IF(T13="","Estimate how much the tool covers",IF(T13>=Lookups!$B$26,IF(AND(R13="Yes",S13="Yes"),"Covered: keep and monitor","Switch on and train people on the existing feature"),"Partial: configure the tool, then fill the gap"))))
A14: U13 | B14: Document-heavy | C14: Cross-industry | D14: Knowledge management | E14: Internal search across files, wikis and chats | F14: People ask colleagues because they can't find documents; knowledge sits in few heads | G14: SharePoint, Drive, wiki, tickets | H14: RAG + LLM | I14: 2 Feature in existing tool | J14: Microsoft Copilot, Google Workspace, Glean; custom RAG | K14: Search time, repeated questions, onboarding time | L14: Showing documents users should not see: permission-aware retrieval | M14: Messy, duplicated documents; clean the content first | N14: High | O14: Medium | U14: =IF(T14="","",1-T14) | V14: =IF(P14="","",IF(Q14="No","No AI in current tool: consider add-on or API-based option",IF(T14="","Estimate how much the tool covers",IF(T14>=Lookups!$B$26,IF(AND(R14="Yes",S14="Yes"),"Covered: keep and monitor","Switch on and train people on the existing feature"),"Partial: configure the tool, then fill the gap"))))
... A55: U54 | B55: Personal service / craft | C55: Small local business | D55: Operations | E55: Booking, reminders and review replies | F55: One to a few people; time lost on messages and scheduling | G55: Calendar, customer messages | H55: LLM | I55: 1 Ready assistant | J55: Booking tools with built-in AI; general assistants | K55: Admin hours per week, no-shows | L55: Low | M55: Hands-on work dominates; no data or repeated digital process | N55: Low | O55: Low | U55: =IF(T55="","",1-T55) | V55: =IF(P55="","",IF(Q55="No","No AI in current tool: consider add-on or API-based option",IF(T55="","Estimate how much the tool covers",IF(T55>=Lookups!$B$26,IF(AND(R55="Yes",S55="Yes"),"Covered: keep and monitor","Switch on and train people on the existing feature"),"Partial: configure the tool, then fill the gap"))))
U56: =IF(T56="","",1-T56) | V56: =IF(P56="","",IF(Q56="No","No AI in current tool: consider add-on or API-based option",IF(T56="","Estimate how much the tool covers",IF(T56>=Lookups!$B$26,IF(AND(R56="Yes",S56="Yes"),"Covered: keep and monitor","Switch on and train people on the existing feature"),"Partial: configure the tool, then fill the gap"))))
U57: =IF(T57="","",1-T57) | V57: =IF(P57="","",IF(Q57="No","No AI in current tool: consider add-on or API-based option",IF(T57="","Estimate how much the tool covers",IF(T57>=Lookups!$B$26,IF(AND(R57="Yes",S57="Yes"),"Covered: keep and monitor","Switch on and train people on the existing feature"),"Partial: configure the tool, then fill the gap"))))
U58: =IF(T58="","",1-T58) | V58: =IF(P58="","",IF(Q58="No","No AI in current tool: consider add-on or API-based option",IF(T58="","Estimate how much the tool covers",IF(T58>=Lookups!$B$26,IF(AND(R58="Yes",S58="Yes"),"Covered: keep and monitor","Switch on and train people on the existing feature"),"Partial: configure the tool, then fill the gap"))))
U59: =IF(T59="","",1-T59) | V59: =IF(P59="","",IF(Q59="No","No AI in current tool: consider add-on or API-based option",IF(T59="","Estimate how much the tool covers",IF(T59>=Lookups!$B$26,IF(AND(R59="Yes",S59="Yes"),"Covered: keep and monitor","Switch on and train people on the existing feature"),"Partial: configure the tool, then fill the gap"))))
U60: =IF(T60="","",1-T60) | V60: =IF(P60="","",IF(Q60="No","No AI in current tool: consider add-on or API-based option",IF(T60="","Estimate how much the tool covers",IF(T60>=Lookups!$B$26,IF(AND(R60="Yes",S60="Yes"),"Covered: keep and monitor","Switch on and train people on the existing feature"),"Partial: configure the tool, then fill the gap"))))
U61: =IF(T61="","",1-T61) | V61: =IF(P61="","",IF(Q61="No","No AI in current tool: consider add-on or API-based option",IF(T61="","Estimate how much the tool covers",IF(T61>=Lookups!$B$26,IF(AND(R61="Yes",S61="Yes"),"Covered: keep and monitor","Switch on and train people on the existing feature"),"Partial: configure the tool, then fill the gap"))))
U62: =IF(T62="","",1-T62) | V62: =IF(P62="","",IF(Q62="No","No AI in current tool: consider add-on or API-based option",IF(T62="","Estimate how much the tool covers",IF(T62>=Lookups!$B$26,IF(AND(R62="Yes",S62="Yes"),"Covered: keep and monitor","Switch on and train people on the existing feature"),"Partial: configure the tool, then fill the gap"))))
U63: =IF(T63="","",1-T63) | V63: =IF(P63="","",IF(Q63="No","No AI in current tool: consider add-on or API-based option",IF(T63="","Estimate how much the tool covers",IF(T63>=Lookups!$B$26,IF(AND(R63="Yes",S63="Yes"),"Covered: keep and monitor","Switch on and train people on the existing feature"),"Partial: configure the tool, then fill the gap"))))
U64: =IF(T64="","",1-T64) | V64: =IF(P64="","",IF(Q64="No","No AI in current tool: consider add-on or API-based option",IF(T64="","Estimate how much the tool covers",IF(T64>=Lookups!$B$26,IF(AND(R64="Yes",S64="Yes"),"Covered: keep and monitor","Switch on and train people on the existing feature"),"Partial: configure the tool, then fill the gap"))))
U65: =IF(T65="","",1-T65) | V65: =IF(P65="","",IF(Q65="No","No AI in current tool: consider add-on or API-based option",IF(T65="","Estimate how much the tool covers",IF(T65>=Lookups!$B$26,IF(AND(R65="Yes",S65="Yes"),"Covered: keep and monitor","Switch on and train people on the existing feature"),"Partial: configure the tool, then fill the gap"))))
U66: =IF(T66="","",1-T66) | V66: =IF(P66="","",IF(Q66="No","No AI in current tool: consider add-on or API-based option",IF(T66="","Estimate how much the tool covers",IF(T66>=Lookups!$B$26,IF(AND(R66="Yes",S66="Yes"),"Covered: keep and monitor","Switch on and train people on the existing feature"),"Partial: configure the tool, then fill the gap"))))
U67: =IF(T67="","",1-T67) | V67: =IF(P67="","",IF(Q67="No","No AI in current tool: consider add-on or API-based option",IF(T67="","Estimate how much the tool covers",IF(T67>=Lookups!$B$26,IF(AND(R67="Yes",S67="Yes"),"Covered: keep and monitor","Switch on and train people on the existing feature"),"Partial: configure the tool, then fill the gap"))))
... U95: =IF(T95="","",1-T95) | V95: =IF(P95="","",IF(Q95="No","No AI in current tool: consider add-on or API-based option",IF(T95="","Estimate how much the tool covers",IF(T95>=Lookups!$B$26,IF(AND(R95="Yes",S95="Yes"),"Covered: keep and monitor","Switch on and train people on the existing feature"),"Partial: configure the tool, then fill the gap"))))

Sheet Forms (what to prescribe)
A1: Form | B1: What the company gets | C1: Typical use | D1: Cost drivers | E1: Main risks | F1: Notes
A2: 1 Ready assistant | B2: Staff get licenses for a chat assistant plus a usage policy | C2: General drafting, summarizing, coding, research by individuals | D2: Per-user subscription, training, policy | E2: Employees paste confidential data; unmanaged accounts | F2: Start here for text work; fastest and cheapest
A3: 2 Feature in existing tool | B3: Switch on or buy an AI add-on in software already owned | C3: CRM, helpdesk, ERP, accounting, office suites | D3: Add-on license, configuration, training | E3: Vendor data sharing; feature never actually adopted | F3: Check first: it may already be paid for
A4: 3 LLM via API | B4: Small custom integration sending specific text to a model and returning results to a system | C4: One well-defined workflow, such as extraction from emails or documents | D4: Developer time, usage billing, testing | E4: Errors in output; vendor terms; integration upkeep | F4: Use when no tool covers the need
A5: 4 RAG on documents | B5: Assistant answering from the company's own documents, with sources | C5: Q&A over policies, manuals, contracts, knowledge bases | D5: Document cleanup, build, access control, evaluation | E5: Outdated documents; users seeing documents they should not | F5: Quality of the documents decides quality of the answers
A6: 5 Private / self-hosted model | B6: Model run on the company's own servers or private cloud | C6: Strict data rules (banks, hospitals, defense) | D6: Hardware or cloud, specialist staff, maintenance | E6: Cost and complexity; model falls behind | F6: Only with a concrete data-control reason
A7: 6 Fine-tuning | B7: Retraining a model on company data for a specific task or style | C7: Narrow high-volume tasks where prompts and RAG fall short | D7: Labeled data, ML staff, re-training | E7: Overfitting; maintenance | F7: Rarely needed
A8: 7 Agent | B8: An LLM that takes multi-step actions in company systems | C8: Workflows already working with human approval | D8: Engineering, testing, monitoring, guardrails | E8: Wrong actions at scale; security (prompt injection) | F8: Last: after forms 1-4 work and approval steps exist
A9: 8 Classical ML project | B9: Predictive model on tables (forecast, churn, fraud, scoring) | C9: Structured historical data with a clear target | D9: Data prep, data scientist, deployment, retraining | E9: Poor data; model not used in decisions | F9: Compare against a simple baseline first
A10: 9 Computer vision project | B10: Model that inspects images or video | C10: Consistent images with enough labeled examples | D10: Cameras, labeling, integration, retraining | E10: Drift when conditions change | F10: High setup cost; confirm volume justifies it
A11: 10 Optimization solver | B11: Mathematical solver for routes, schedules, allocation | C11: Clear constraints and costs | D11: Modeling, data feeds, user acceptance | E11: Reality missing from model | F11: Often not 'AI' at all; sometimes the best answer
A12: 11 Plain automation / process fix | B12: Rules, workflows, integrations or a process change | C12: Repeated, fixed-step work | D12: Low: workflow tools and process redesign | E12: Automating a bad process | F12: Always check this first

Sheet When AI is not needed
A1: Situation | B1: Why AI usually does not help | C1: What to recommend instead
A2: Small team (a few people), hands-on work (barber, plumber, small cafe) | B2: Work is physical and personal; little data | C2: Built-in AI features of booking, accounting or messaging tools; a general assistant for admin
A3: Bottleneck is capacity, location or skilled hands | B3: AI processes information; it can't add trucks, rooms or technicians | C3: Capacity planning, hiring, process redesign
A4: Every job is unique and little is repeated | B4: Nothing to learn from; no repetition to automate | C4: Better templates, knowledge sharing
A5: Process is broken, not slow | B5: Automating a bad process makes errors faster | C5: Fix the process, then reassess
A6: Fixed-step, rule-based work | B6: Rules or workflow tools are cheaper, exact and explainable | C6: Plain automation (form 11)
A7: Little or no data, no way to collect it | B7: ML needs examples; LLMs need text or documents to work on | C7: Start collecting data in a structured way
A8: Documents or knowledge are outdated or contradictory | B8: Assistants repeat bad content faster | C8: Clean and own the content first
A9: Mistakes are unaffordable and no human check is possible | B9: AI is probabilistic | C9: Keep deterministic software and human review
A10: No owner, no champion, vague goal ('we just want AI') | B10: Projects stall without an accountable owner | C10: Run a short workshop; revisit when an owner exists
A11: Simple statistics already solve it | B11: A moving average or rule may match an ML model | C11: Test the simple baseline before any ML work

Sheet Summary
A1: Summary (updates from Use Case Master)
A3: By business type | B3: Use cases | C3: High / Very high need
A4: Document-heavy | B4: =COUNTIF('Use Case Master'!$B$2:$B$95,A4) -> 13 | C4: =COUNTIFS('Use Case Master'!$B$2:$B$95,A4,'Use Case Master'!$N$2:$N$95,"Very high")+COUNTIFS('Use Case Master'!$B$2:$B$95,A4,'Use Case Master'!$N$2:$N$95,"High") -> 11
A5: Transaction-heavy | B5: =COUNTIF('Use Case Master'!$B$2:$B$95,A5) -> 18 | C5: =COUNTIFS('Use Case Master'!$B$2:$B$95,A5,'Use Case Master'!$N$2:$N$95,"Very high")+COUNTIFS('Use Case Master'!$B$2:$B$95,A5,'Use Case Master'!$N$2:$N$95,"High") -> 10
A6: Physical operations | B6: =COUNTIF('Use Case Master'!$B$2:$B$95,A6) -> 7 | C6: =COUNTIFS('Use Case Master'!$B$2:$B$95,A6,'Use Case Master'!$N$2:$N$95,"Very high")+COUNTIFS('Use Case Master'!$B$2:$B$95,A6,'Use Case Master'!$N$2:$N$95,"High") -> 3
A7: Conversation-heavy | B7: =COUNTIF('Use Case Master'!$B$2:$B$95,A7) -> 10 | C7: =COUNTIFS('Use Case Master'!$B$2:$B$95,A7,'Use Case Master'!$N$2:$N$95,"Very high")+COUNTIFS('Use Case Master'!$B$2:$B$95,A7,'Use Case Master'!$N$2:$N$95,"High") -> 6
A8: Expert judgment | B8: =COUNTIF('Use Case Master'!$B$2:$B$95,A8) -> 5 | C8: =COUNTIFS('Use Case Master'!$B$2:$B$95,A8,'Use Case Master'!$N$2:$N$95,"Very high")+COUNTIFS('Use Case Master'!$B$2:$B$95,A8,'Use Case Master'!$N$2:$N$95,"High") -> 1
A9: Personal service / craft | B9: =COUNTIF('Use Case Master'!$B$2:$B$95,A9) -> 1 | C9: =COUNTIFS('Use Case Master'!$B$2:$B$95,A9,'Use Case Master'!$N$2:$N$95,"Very high")+COUNTIFS('Use Case Master'!$B$2:$B$95,A9,'Use Case Master'!$N$2:$N$95,"High") -> 0
A11: By industry | B11: Use cases | C11: High / Very high need
A12: Cross-industry | B12: =COUNTIF('Use Case Master'!$C$2:$C$95,A12) -> 14 | C12: =COUNTIFS('Use Case Master'!$C$2:$C$95,A12,'Use Case Master'!$N$2:$N$95,"Very high")+COUNTIFS('Use Case Master'!$C$2:$C$95,A12,'Use Case Master'!$N$2:$N$95,"High") -> 9
A13: Banking | B13: =COUNTIF('Use Case Master'!$C$2:$C$95,A13) -> 4 | C13: =COUNTIFS('Use Case Master'!$C$2:$C$95,A13,'Use Case Master'!$N$2:$N$95,"Very high")+COUNTIFS('Use Case Master'!$C$2:$C$95,A13,'Use Case Master'!$N$2:$N$95,"High") -> 3
A14: Insurance | B14: =COUNTIF('Use Case Master'!$C$2:$C$95,A14) -> 3 | C14: =COUNTIFS('Use Case Master'!$C$2:$C$95,A14,'Use Case Master'!$N$2:$N$95,"Very high")+COUNTIFS('Use Case Master'!$C$2:$C$95,A14,'Use Case Master'!$N$2:$N$95,"High") -> 3
A15: E-commerce | B15: =COUNTIF('Use Case Master'!$C$2:$C$95,A15) -> 4 | C15: =COUNTIFS('Use Case Master'!$C$2:$C$95,A15,'Use Case Master'!$N$2:$N$95,"Very high")+COUNTIFS('Use Case Master'!$C$2:$C$95,A15,'Use Case Master'!$N$2:$N$95,"High") -> 3
A16: Retail (physical) | B16: =COUNTIF('Use Case Master'!$C$2:$C$95,A16) -> 2 | C16: =COUNTIFS('Use Case Master'!$C$2:$C$95,A16,'Use Case Master'!$N$2:$N$95,"Very high")+COUNTIFS('Use Case Master'!$C$2:$C$95,A16,'Use Case Master'!$N$2:$N$95,"High") -> 1
A17: Logistics | B17: =COUNTIF('Use Case Master'!$C$2:$C$95,A17) -> 3 | C17: =COUNTIFS('Use Case Master'!$C$2:$C$95,A17,'Use Case Master'!$N$2:$N$95,"Very high")+COUNTIFS('Use Case Master'!$C$2:$C$95,A17,'Use Case Master'!$N$2:$N$95,"High") -> 2
A18: Manufacturing | B18: =COUNTIF('Use Case Master'!$C$2:$C$95,A18) -> 4 | C18: =COUNTIFS('Use Case Master'!$C$2:$C$95,A18,'Use Case Master'!$N$2:$N$95,"Very high")+COUNTIFS('Use Case Master'!$C$2:$C$95,A18,'Use Case Master'!$N$2:$N$95,"High") -> 2
A19: Healthcare | B19: =COUNTIF('Use Case Master'!$C$2:$C$95,A19) -> 2 | C19: =COUNTIFS('Use Case Master'!$C$2:$C$95,A19,'Use Case Master'!$N$2:$N$95,"Very high")+COUNTIFS('Use Case Master'!$C$2:$C$95,A19,'Use Case Master'!$N$2:$N$95,"High") -> 0
A20: Law / Accounting | B20: =COUNTIF('Use Case Master'!$C$2:$C$95,A20) -> 2 | C20: =COUNTIFS('Use Case Master'!$C$2:$C$95,A20,'Use Case Master'!$N$2:$N$95,"Very high")+COUNTIFS('Use Case Master'!$C$2:$C$95,A20,'Use Case Master'!$N$2:$N$95,"High") -> 2
A21: Telecom | B21: =COUNTIF('Use Case Master'!$C$2:$C$95,A21) -> 2 | C21: =COUNTIFS('Use Case Master'!$C$2:$C$95,A21,'Use Case Master'!$N$2:$N$95,"Very high")+COUNTIFS('Use Case Master'!$C$2:$C$95,A21,'Use Case Master'!$N$2:$N$95,"High") -> 1
A22: Energy / Utilities | B22: =COUNTIF('Use Case Master'!$C$2:$C$95,A22) -> 2 | C22: =COUNTIFS('Use Case Master'!$C$2:$C$95,A22,'Use Case Master'!$N$2:$N$95,"Very high")+COUNTIFS('Use Case Master'!$C$2:$C$95,A22,'Use Case Master'!$N$2:$N$95,"High") -> 1
A23: Agriculture | B23: =COUNTIF('Use Case Master'!$C$2:$C$95,A23) -> 1 | C23: =COUNTIFS('Use Case Master'!$C$2:$C$95,A23,'Use Case Master'!$N$2:$N$95,"Very high")+COUNTIFS('Use Case Master'!$C$2:$C$95,A23,'Use Case Master'!$N$2:$N$95,"High") -> 0
... A29: Small local business | B29: =COUNTIF('Use Case Master'!$C$2:$C$95,A29) -> 1 | C29: =COUNTIFS('Use Case Master'!$C$2:$C$95,A29,'Use Case Master'!$N$2:$N$95,"Very high")+COUNTIFS('Use Case Master'!$C$2:$C$95,A29,'Use Case Master'!$N$2:$N$95,"High") -> 0
A31: By form | B31: Use cases | C31: High / Very high need
A32: 1 Ready assistant | B32: =COUNTIF('Use Case Master'!$I$2:$I$95,A32) -> 4 | C32: =COUNTIFS('Use Case Master'!$I$2:$I$95,A32,'Use Case Master'!$N$2:$N$95,"Very high")+COUNTIFS('Use Case Master'!$I$2:$I$95,A32,'Use Case Master'!$N$2:$N$95,"High") -> 1
A33: 2 Feature in existing tool | B33: =COUNTIF('Use Case Master'!$I$2:$I$95,A33) -> 14 | C33: =COUNTIFS('Use Case Master'!$I$2:$I$95,A33,'Use Case Master'!$N$2:$N$95,"Very high")+COUNTIFS('Use Case Master'!$I$2:$I$95,A33,'Use Case Master'!$N$2:$N$95,"High") -> 9
A34: 3 LLM via API | B34: =COUNTIF('Use Case Master'!$I$2:$I$95,A34) -> 10 | C34: =COUNTIFS('Use Case Master'!$I$2:$I$95,A34,'Use Case Master'!$N$2:$N$95,"Very high")+COUNTIFS('Use Case Master'!$I$2:$I$95,A34,'Use Case Master'!$N$2:$N$95,"High") -> 8
A35: 4 RAG on documents | B35: =COUNTIF('Use Case Master'!$I$2:$I$95,A35) -> 5 | C35: =COUNTIFS('Use Case Master'!$I$2:$I$95,A35,'Use Case Master'!$N$2:$N$95,"Very high")+COUNTIFS('Use Case Master'!$I$2:$I$95,A35,'Use Case Master'!$N$2:$N$95,"High") -> 2
A36: 5 Private / self-hosted model | B36: =COUNTIF('Use Case Master'!$I$2:$I$95,A36) -> 0 | C36: =COUNTIFS('Use Case Master'!$I$2:$I$95,A36,'Use Case Master'!$N$2:$N$95,"Very high")+COUNTIFS('Use Case Master'!$I$2:$I$95,A36,'Use Case Master'!$N$2:$N$95,"High") -> 0
A37: 6 Fine-tuning | B37: =COUNTIF('Use Case Master'!$I$2:$I$95,A37) -> 0 | C37: =COUNTIFS('Use Case Master'!$I$2:$I$95,A37,'Use Case Master'!$N$2:$N$95,"Very high")+COUNTIFS('Use Case Master'!$I$2:$I$95,A37,'Use Case Master'!$N$2:$N$95,"High") -> 0
A38: 7 Agent | B38: =COUNTIF('Use Case Master'!$I$2:$I$95,A38) -> 0 | C38: =COUNTIFS('Use Case Master'!$I$2:$I$95,A38,'Use Case Master'!$N$2:$N$95,"Very high")+COUNTIFS('Use Case Master'!$I$2:$I$95,A38,'Use Case Master'!$N$2:$N$95,"High") -> 0
A39: 8 Classical ML project | B39: =COUNTIF('Use Case Master'!$I$2:$I$95,A39) -> 16 | C39: =COUNTIFS('Use Case Master'!$I$2:$I$95,A39,'Use Case Master'!$N$2:$N$95,"Very high")+COUNTIFS('Use Case Master'!$I$2:$I$95,A39,'Use Case Master'!$N$2:$N$95,"High") -> 9
A40: 9 Computer vision project | B40: =COUNTIF('Use Case Master'!$I$2:$I$95,A40) -> 3 | C40: =COUNTIFS('Use Case Master'!$I$2:$I$95,A40,'Use Case Master'!$N$2:$N$95,"Very high")+COUNTIFS('Use Case Master'!$I$2:$I$95,A40,'Use Case Master'!$N$2:$N$95,"High") -> 1
A41: 10 Optimization solver | B41: =COUNTIF('Use Case Master'!$I$2:$I$95,A41) -> 2 | C41: =COUNTIFS('Use Case Master'!$I$2:$I$95,A41,'Use Case Master'!$N$2:$N$95,"Very high")+COUNTIFS('Use Case Master'!$I$2:$I$95,A41,'Use Case Master'!$N$2:$N$95,"High") -> 1
A42: 11 Plain automation / process fix | B42: =COUNTIF('Use Case Master'!$I$2:$I$95,A42) -> 0 | C42: =COUNTIFS('Use Case Master'!$I$2:$I$95,A42,'Use Case Master'!$N$2:$N$95,"Very high")+COUNTIFS('Use Case Master'!$I$2:$I$95,A42,'Use Case Master'!$N$2:$N$95,"High") -> 0
A44: By technology | B44: Use cases | C44: High / Very high need
A45: Classical ML | B45: =COUNTIF('Use Case Master'!$H$2:$H$95,A45) -> 14 | C45: =COUNTIFS('Use Case Master'!$H$2:$H$95,A45,'Use Case Master'!$N$2:$N$95,"Very high")+COUNTIFS('Use Case Master'!$H$2:$H$95,A45,'Use Case Master'!$N$2:$N$95,"High") -> 8
A46: Anomaly detection | B46: =COUNTIF('Use Case Master'!$H$2:$H$95,A46) -> 4 | C46: =COUNTIFS('Use Case Master'!$H$2:$H$95,A46,'Use Case Master'!$N$2:$N$95,"Very high")+COUNTIFS('Use Case Master'!$H$2:$H$95,A46,'Use Case Master'!$N$2:$N$95,"High") -> 2
A47: LLM | B47: =COUNTIF('Use Case Master'!$H$2:$H$95,A47) -> 6 | C47: =COUNTIFS('Use Case Master'!$H$2:$H$95,A47,'Use Case Master'!$N$2:$N$95,"Very high")+COUNTIFS('Use Case Master'!$H$2:$H$95,A47,'Use Case Master'!$N$2:$N$95,"High") -> 2
A48: RAG + LLM | B48: =COUNTIF('Use Case Master'!$H$2:$H$95,A48) -> 11 | C48: =COUNTIFS('Use Case Master'!$H$2:$H$95,A48,'Use Case Master'!$N$2:$N$95,"Very high")+COUNTIFS('Use Case Master'!$H$2:$H$95,A48,'Use Case Master'!$N$2:$N$95,"High") -> 7
A49: VLM | B49: =COUNTIF('Use Case Master'!$H$2:$H$95,A49) -> 2 | C49: =COUNTIFS('Use Case Master'!$H$2:$H$95,A49,'Use Case Master'!$N$2:$N$95,"Very high")+COUNTIFS('Use Case Master'!$H$2:$H$95,A49,'Use Case Master'!$N$2:$N$95,"High") -> 1
...

Sheet Lookups
A1: Business type | B1: Industry | C1: Department | D1: Technology | E1: Form | F1: Need level | G1: Risk | H1: Cost range | I1: Yes/No/Unknown
A2: Document-heavy | B2: Cross-industry | C2: Customer service | D2: Classical ML | E2: 1 Ready assistant | F2: Very high | G2: Low | H2: Low | I2: Yes
A3: Transaction-heavy | B3: Banking | C3: Sales & marketing | D3: Anomaly detection | E3: 2 Feature in existing tool | F3: High | G3: Medium | H3: Medium | I3: No
A4: Physical operations | B4: Insurance | C4: Finance & accounting | D4: LLM | E4: 3 LLM via API | F4: Medium | G4: High | H4: High | I4: Unknown
A5: Conversation-heavy | B5: E-commerce | C5: Operations | D5: RAG + LLM | E5: 4 RAG on documents | F5: Low
A6: Expert judgment | B6: Retail (physical) | C6: HR | D6: VLM | E6: 5 Private / self-hosted model
A7: Personal service / craft | B7: Logistics | C7: Legal & compliance | D7: Computer vision | E7: 6 Fine-tuning
B8: Manufacturing | C8: IT | D8: Document AI + LLM | E8: 7 Agent
B9: Healthcare | C9: Quality & maintenance | D9: Document AI + VLM | E9: 8 Classical ML project
B10: Law / Accounting | C10: Risk | D10: Recommender | E10: 9 Computer vision project
B11: Telecom | C11: Claims | D11: Optimization | E11: 10 Optimization solver
B12: Energy / Utilities | C12: Underwriting | D12: Speech-to-text + LLM | E12: 11 Plain automation / process fix
B13: Agriculture | C13: Catalog | D13: Plain automation
B14: Education | C14: Planning
B15: Government | C15: Warehouse
B16: Hospitality | C16: Back office
B17: Construction / Real estate | C17: Clinical / admin
B18: Software / SaaS | C18: Core work
B19: Small local business | C19: Knowledge management
A25: Assumptions
A26: Tool covers the need at or above | B26: 0.7
A27: Rule of thumb (about 70-80%) - adjust as you see fit. Edit the lists above to change dropdowns.
